Workbook

Sheet Top Countries $
A1: INTERNATIONAL TOP COUNTRIES $
A4: The numbers in the table below are FICTICIOUS
A6: Month | B6: Order | C6: Country | D6: Total
A8: 45474 | B8: 1 | C8: United States of America | D8: 3600
A9: 45474 | B9: 2 | C9: New Zealand | D9: 23000
A10: 45474 | B10: 3 | C10: Great Britain | D10: 3000
A11: 45474 | B11: 4 | C11: South Africa | D11: 2500
A12: 45474 | B12: 5 | C12: Australia | D12: 1500
A13: 45474 | B13: 6 | C13: Canada | D13: 1100
A14: 45474 | B14: 7 | C14: Germany | D14: 800
A15: 45474 | B15: 8 | C15: Ireland | D15: 600
A16: 45474 | B16: 9 | C16: Israel | D16: 400
A17: 45474 | B17: 10 | C17: Malta | D17: 100
A18: 45474 | B18: 11 | C18: Other | D18: 300
A19: 45474 | C19: Total | D19: =SUM(D8:D18) -> 36900
A20: 45505 | B20: 1 | C20: New Zealand | D20: 16000
A21: 45505 | B21: 2 | C21: United States of America | D21: 3600
A22: 45505 | B22: 3 | C22: Australia | D22: 2500
A23: 45505 | B23: 4 | C23: Great Britain | D23: 1600
A24: 45505 | B24: 5 | C24: South Africa | D24: 1200
A25: 45505 | B25: 6 | C25: India | D25: 800
A26: 45505 | B26: 7 | C26: Canada | D26: 600
A27: 45505 | B27: 8 | C27: Denmark | D27: 300
A28: 45505 | B28: 9 | C28: Italy | D28: 100
A29: 45505 | B29: 10 | C29: Norway | D29: 100
A30: 45505 | B30: 11 | C30: Other | D30: 2000
A31: 45505 | C31: Total | D31: =SUM(D20:D30) -> 28800
A32: 45536 | B32: 1 | C32: New Zealand | D32: 23000
A33: 45536 | B33: 2 | C33: United States of America | D33: 3600
A34: 45536 | B34: 3 | C34: Australia | D34: 2200
A35: 45536 | B35: 4 | C35: Other | D35: 1900
A36: 45536 | B36: 5 | C36: South Africa | D36: 1500
A37: 45536 | B37: 6 | C37: Canada | D37: 1000
A38: 45536 | B38: 7 | C38: Great Britain | D38: 800
A39: 45536 | B39: 8 | C39: Americas | D39: 500
A40: 45536 | B40: 9 | C40: Denmark | D40: 300
A41: 45536 | B41: 10 | C41: India | D41: 300
A42: 45536 | B42: 11 | C42: Germany | D42: 100
A43: 45536 | C43: Total | D43: =SUM(D32:D42) -> 35200
A44: 45566 | B44: 1 | C44: New Zealand | D44: 15000
...

Sheet Income Source $
B1: INCOME SOURCE $ | F1: The numbers in the table below are FICTICIOUS
B4: Month | C4: Country | D4: Licencing | E4: Marketing Support | F4: Other | G4: Product Sales | H4: Shipping | I4: Apple | J4: Google | K4: Website (Stripe) | L4: Invoices | M4: Resellers | N4: Total
B6: 45474 | C6: Total | D6: 2000 | E6: 500 | F6: =N6-D6-E6-SUM(G6:M6) -> 6800 | G6: 3500 | H6: 100 | I6: 1000 | J6: 3000 | K6: 18000 | L6: 1000 | M6: 1000 | N6: ='Top Countries $'!D19 -> 36900
B7: 45505 | C7: Total | D7: 2000 | E7: 0 | F7: =N7-D7-E7-SUM(G7:M7) -> 1050 | G7: 3000 | H7: 150 | I7: 1200 | J7: 3200 | K7: 16000 | L7: 1000 | M7: 1200 | N7: ='Top Countries $'!D31 -> 28800
B8: 45536 | C8: Total | D8: 2000 | E8: 0 | F8: =N8-D8-E8-SUM(G8:M8) -> 1850 | G8: 3000 | H8: 150 | I8: 1400 | J8: 3400 | K8: 21000 | L8: 1200 | M8: 1200 | N8: ='Top Countries $'!D43 -> 35200
B9: 45566 | C9: Total | D9: 2000 | E9: 1500 | F9: =N9-D9-E9-SUM(G9:M9) -> 1650 | G9: 3000 | H9: 150 | I9: 1600 | J9: 3600 | K9: 16000 | L9: 1200 | M9: 1200 | N9: ='Top Countries $'!D55 -> 31900
B10: 45597 | C10: Total | D10: 2000 | E10: 0 | F10: =N10-D10-E10-SUM(G10:M10) -> 1400 | G10: 3000 | H10: 200 | I10: 1800 | J10: 3800 | K10: 12000 | L10: 1600 | M10: 1600 | N10: ='Top Countries $'!D67 -> 27400
B11: 45627 | C11: Total | D11: 2000 | E11: 0 | F11: =N11-D11-E11-SUM(G11:M11) -> 6780 | G11: 3000 | H11: 200 | I11: 2000 | J11: 4000 | K11: 26000 | L11: 1600 | M11: 1600 | N11: ='Top Countries $'!D79 -> 47180
B12: 45658 | C12: Total | D12: 2000 | E12: 5000 | F12: =N12-D12-E12-SUM(G12:M12) -> 1450 | G12: 2800 | H12: 250 | I12: 2200 | J12: 4200 | K12: 15500 | L12: 1400 | M12: 1800 | N12: ='Top Countries $'!D91 -> 36600
B13: 45689 | C13: Total | D13: 2000 | E13: 0 | F13: =N13-D13-E13-SUM(G13:M13) -> 2680 | G13: 2500 | H13: 250 | I13: 2400 | J13: 4400 | K13: 18000 | L13: 1400 | M13: 1800 | N13: ='Top Countries $'!D103 -> 35430
B14: 45717 | C14: Total | D14: 2000 | E14: 0 | F14: =N14-D14-E14-SUM(G14:M14) -> 6000 | G14: 2500 | H14: 300 | I14: 2600 | J14: 4600 | K14: 30000 | L14: 1200 | M14: 1800 | N14: ='Top Countries $'!D115 -> 51000
B15: 45748 | C15: Total | D15: 2000 | E15: 0 | F15: =N15-D15-E15-SUM(G15:M15) -> 6780 | G15: 2000 | H15: 200 | I15: 2800 | J15: 4800 | K15: 20000 | L15: 1200 | M15: 2000 | N15: ='Top Countries $'!D127 -> 41780
B16: 45778 | C16: Total | D16: 2000 | E16: 0 | F16: =N16-D16-E16-SUM(G16:M16) -> 6380 | G16: 3000 | H16: 400 | I16: 3000 | J16: 5000 | K16: 26500 | L16: 1000 | M16: 2000 | N16: ='Top Countries $'!D139 -> 49280
B17: 45809 | C17: Total | D17: 2000 | E17: 0 | F17: =N17-D17-E17-SUM(G17:M17) -> 9950 | G17: 1800 | H17: 200 | I17: 3200 | J17: 5200 | K17: 18000 | L17: 1000 | M17: 1200 | N17: ='Top Countries $'!D151 -> 42550
B18: 45839 | C18: Total | D18: 2000 | E18: 0 | F18: =N18-D18-E18-SUM(G18:M18) -> 9400 | G18: 3000 | H18: 200 | I18: 3400 | J18: 5400 | K18: 30000 | L18: 1600 | M18: 1200 | N18: ='Top Countries $'!D163 -> 56200
B19: 45870 | C19: Total | D19: 2000 | E19: 0 | F19: =N19-D19-E19-SUM(G19:M19) -> 7280 | G19: 3000 | H19: 200 | I19: 3600 | J19: 5600 | K19: 17000 | L19: 1650 | M19: 1200 | N19: ='Top Countries $'!D175 -> 41530
B20: 45901 | C20: Total | D20: 2000 | E20: 0 | F20: =N20-D20-E20-SUM(G20:M20) -> 6150 | G20: 2500 | H20: 550 | I20: 3800 | J20: 5800 | K20: 25000 | L20: 1800 | M20: 1500 | N20: ='Top Countries $'!D187 -> 49100
B21: 45931 | C21: Total | D21: 2000 | E21: 0 | F21: =N21-D21-E21-SUM(G21:M21) -> 7900 | G21: 2300 | H21: 500 | I21: 4000 | J21: 6000 | K21: 18000 | L21: 1800 | M21: 1500 | N21: ='Top Countries $'!D199 -> 44000
B22: 45962 | C22: Total | D22: 2000 | E22: 0 | F22: =N22-D22-E22-SUM(G22:M22) -> 7200 | G22: 2000 | H22: 350 | I22: 4200 | J22: 6200 | K22: 15000 | L22: 1850 | M22: 1200 | N22: ='Top Countries $'!D211 -> 40000
B23: 45992 | C23: Total | D23: 2000 | E23: 0 | F23: =N23-D23-E23-SUM(G23:M23) -> 7000 | G23: 2500 | H23: 400 | I23: 4400 | J23: 6400 | K23: 24000 | L23: 1900 | M23: 1300 | N23: ='Top Countries $'!D223 -> 49900
B24: 46023 | C24: Total | D24: 2000 | E24: 0 | F24: =N24-D24-E24-SUM(G24:M24) -> 17900 | G24: 2500 | H24: 400 | I24: 4500 | J24: 7200 | K24: 32000 | L24: 2000 | M24: 1500 | N24: ='Top Countries $'!D235 -> 70000
B25: 46054 | C25: Total | D25: 2000 | E25: 0 | F25: =N25-D25-E25-SUM(G25:M25) -> 15150 | G25: 3000 | H25: 600 | I25: 5000 | J25: 7000 | K25: 25000 | L25: 3000 | M25: 2500 | N25: ='Top Countries $'!D247 -> 63250
